Traceback (most recent call last):
  File "/home/kyle/Documents/research/personal/hubway-expansion/code/01gbfs_scrape.py", line 2, in <module>
    import pandas as pd
ImportError: No module named 'pandas'
Traceback (most recent call last):
  File "/home/kyle/Documents/research/personal/hubway-expansion/code/01gbfs_scrape.py", line 2, in <module>
    import pandas as pd
ImportError: No module named 'pandas'
Traceback (most recent call last):
  File "/home/kyle/opt/anaconda3/lib/python3.6/site-packages/urllib3/connection.py", line 141, in _new_conn
    (self.host, self.port), self.timeout, **extra_kw)
  File "/home/kyle/opt/anaconda3/lib/python3.6/site-packages/urllib3/util/connection.py", line 60, in create_connection
    for res in socket.getaddrinfo(host, port, family, socket.SOCK_STREAM):
  File "/home/kyle/opt/anaconda3/lib/python3.6/socket.py", line 743, in getaddrinfo
    for res in _socket.getaddrinfo(host, port, family, type, proto, flags):
socket.gaierror: [Errno -2] Name or service not known

During handling of the above exception, another exception occurred:

Traceback (most recent call last):
  File "/home/kyle/opt/anaconda3/lib/python3.6/site-packages/urllib3/connectionpool.py", line 601, in urlopen
    chunked=chunked)
  File "/home/kyle/opt/anaconda3/lib/python3.6/site-packages/urllib3/connectionpool.py", line 346, in _make_request
    self._validate_conn(conn)
  File "/home/kyle/opt/anaconda3/lib/python3.6/site-packages/urllib3/connectionpool.py", line 850, in _validate_conn
    conn.connect()
  File "/home/kyle/opt/anaconda3/lib/python3.6/site-packages/urllib3/connection.py", line 284, in connect
    conn = self._new_conn()
  File "/home/kyle/opt/anaconda3/lib/python3.6/site-packages/urllib3/connection.py", line 150, in _new_conn
    self, "Failed to establish a new connection: %s" % e)
urllib3.exceptions.NewConnectionError: <urllib3.connection.VerifiedHTTPSConnection object at 0x7f40f6020f98>: Failed to establish a new connection: [Errno -2] Name or service not known

During handling of the above exception, another exception occurred:

Traceback (most recent call last):
  File "/home/kyle/opt/anaconda3/lib/python3.6/site-packages/requests/adapters.py", line 440, in send
    timeout=timeout
  File "/home/kyle/opt/anaconda3/lib/python3.6/site-packages/urllib3/connectionpool.py", line 639, in urlopen
    _stacktrace=sys.exc_info()[2])
  File "/home/kyle/opt/anaconda3/lib/python3.6/site-packages/urllib3/util/retry.py", line 388, in increment
    raise MaxRetryError(_pool, url, error or ResponseError(cause))
urllib3.exceptions.MaxRetryError: HTTPSConnectionPool(host='gbfs.thehubway.com', port=443): Max retries exceeded with url: /gbfs/en/station_status.json (Caused by NewConnectionError('<urllib3.connection.VerifiedHTTPSConnection object at 0x7f40f6020f98>: Failed to establish a new connection: [Errno -2] Name or service not known',))

During handling of the above exception, another exception occurred:

Traceback (most recent call last):
  File "/home/kyle/Documents/research/personal/hubway-expansion/code/01gbfs_scrape.py", line 16, in <module>
    data_station_status = requests.get(url_station_status).json()
  File "/home/kyle/opt/anaconda3/lib/python3.6/site-packages/requests/api.py", line 72, in get
    return request('get', url, params=params, **kwargs)
  File "/home/kyle/opt/anaconda3/lib/python3.6/site-packages/requests/api.py", line 58, in request
    return session.request(method=method, url=url, **kwargs)
  File "/home/kyle/opt/anaconda3/lib/python3.6/site-packages/requests/sessions.py", line 508, in request
    resp = self.send(prep, **send_kwargs)
  File "/home/kyle/opt/anaconda3/lib/python3.6/site-packages/requests/sessions.py", line 618, in send
    r = adapter.send(request, **kwargs)
  File "/home/kyle/opt/anaconda3/lib/python3.6/site-packages/requests/adapters.py", line 508, in send
    raise ConnectionError(e, request=request)
requests.exceptions.ConnectionError: HTTPSConnectionPool(host='gbfs.thehubway.com', port=443): Max retries exceeded with url: /gbfs/en/station_status.json (Caused by NewConnectionError('<urllib3.connection.VerifiedHTTPSConnection object at 0x7f40f6020f98>: Failed to establish a new connection: [Errno -2] Name or service not known',))
Traceback (most recent call last):
  File "/home/kyle/opt/anaconda3/lib/python3.6/site-packages/urllib3/connection.py", line 141, in _new_conn
    (self.host, self.port), self.timeout, **extra_kw)
  File "/home/kyle/opt/anaconda3/lib/python3.6/site-packages/urllib3/util/connection.py", line 60, in create_connection
    for res in socket.getaddrinfo(host, port, family, socket.SOCK_STREAM):
  File "/home/kyle/opt/anaconda3/lib/python3.6/socket.py", line 743, in getaddrinfo
    for res in _socket.getaddrinfo(host, port, family, type, proto, flags):
socket.gaierror: [Errno -2] Name or service not known

During handling of the above exception, another exception occurred:

Traceback (most recent call last):
  File "/home/kyle/opt/anaconda3/lib/python3.6/site-packages/urllib3/connectionpool.py", line 601, in urlopen
    chunked=chunked)
  File "/home/kyle/opt/anaconda3/lib/python3.6/site-packages/urllib3/connectionpool.py", line 346, in _make_request
    self._validate_conn(conn)
  File "/home/kyle/opt/anaconda3/lib/python3.6/site-packages/urllib3/connectionpool.py", line 850, in _validate_conn
    conn.connect()
  File "/home/kyle/opt/anaconda3/lib/python3.6/site-packages/urllib3/connection.py", line 284, in connect
    conn = self._new_conn()
  File "/home/kyle/opt/anaconda3/lib/python3.6/site-packages/urllib3/connection.py", line 150, in _new_conn
    self, "Failed to establish a new connection: %s" % e)
urllib3.exceptions.NewConnectionError: <urllib3.connection.VerifiedHTTPSConnection object at 0x7fe4aa83bf28>: Failed to establish a new connection: [Errno -2] Name or service not known

During handling of the above exception, another exception occurred:

Traceback (most recent call last):
  File "/home/kyle/opt/anaconda3/lib/python3.6/site-packages/requests/adapters.py", line 440, in send
    timeout=timeout
  File "/home/kyle/opt/anaconda3/lib/python3.6/site-packages/urllib3/connectionpool.py", line 639, in urlopen
    _stacktrace=sys.exc_info()[2])
  File "/home/kyle/opt/anaconda3/lib/python3.6/site-packages/urllib3/util/retry.py", line 388, in increment
    raise MaxRetryError(_pool, url, error or ResponseError(cause))
urllib3.exceptions.MaxRetryError: HTTPSConnectionPool(host='gbfs.thehubway.com', port=443): Max retries exceeded with url: /gbfs/en/station_status.json (Caused by NewConnectionError('<urllib3.connection.VerifiedHTTPSConnection object at 0x7fe4aa83bf28>: Failed to establish a new connection: [Errno -2] Name or service not known',))

During handling of the above exception, another exception occurred:

Traceback (most recent call last):
  File "/home/kyle/Documents/research/personal/hubway-expansion/code/01gbfs_scrape.py", line 16, in <module>
    data_station_status = requests.get(url_station_status).json()
  File "/home/kyle/opt/anaconda3/lib/python3.6/site-packages/requests/api.py", line 72, in get
    return request('get', url, params=params, **kwargs)
  File "/home/kyle/opt/anaconda3/lib/python3.6/site-packages/requests/api.py", line 58, in request
    return session.request(method=method, url=url, **kwargs)
  File "/home/kyle/opt/anaconda3/lib/python3.6/site-packages/requests/sessions.py", line 508, in request
    resp = self.send(prep, **send_kwargs)
  File "/home/kyle/opt/anaconda3/lib/python3.6/site-packages/requests/sessions.py", line 618, in send
    r = adapter.send(request, **kwargs)
  File "/home/kyle/opt/anaconda3/lib/python3.6/site-packages/requests/adapters.py", line 508, in send
    raise ConnectionError(e, request=request)
requests.exceptions.ConnectionError: HTTPSConnectionPool(host='gbfs.thehubway.com', port=443): Max retries exceeded with url: /gbfs/en/station_status.json (Caused by NewConnectionError('<urllib3.connection.VerifiedHTTPSConnection object at 0x7fe4aa83bf28>: Failed to establish a new connection: [Errno -2] Name or service not known',))
Traceback (most recent call last):
  File "/home/kyle/opt/anaconda3/lib/python3.6/site-packages/urllib3/connection.py", line 141, in _new_conn
    (self.host, self.port), self.timeout, **extra_kw)
  File "/home/kyle/opt/anaconda3/lib/python3.6/site-packages/urllib3/util/connection.py", line 60, in create_connection
    for res in socket.getaddrinfo(host, port, family, socket.SOCK_STREAM):
  File "/home/kyle/opt/anaconda3/lib/python3.6/socket.py", line 743, in getaddrinfo
    for res in _socket.getaddrinfo(host, port, family, type, proto, flags):
socket.gaierror: [Errno -2] Name or service not known

During handling of the above exception, another exception occurred:

Traceback (most recent call last):
  File "/home/kyle/opt/anaconda3/lib/python3.6/site-packages/urllib3/connectionpool.py", line 601, in urlopen
    chunked=chunked)
  File "/home/kyle/opt/anaconda3/lib/python3.6/site-packages/urllib3/connectionpool.py", line 346, in _make_request
    self._validate_conn(conn)
  File "/home/kyle/opt/anaconda3/lib/python3.6/site-packages/urllib3/connectionpool.py", line 850, in _validate_conn
    conn.connect()
  File "/home/kyle/opt/anaconda3/lib/python3.6/site-packages/urllib3/connection.py", line 284, in connect
    conn = self._new_conn()
  File "/home/kyle/opt/anaconda3/lib/python3.6/site-packages/urllib3/connection.py", line 150, in _new_conn
    self, "Failed to establish a new connection: %s" % e)
urllib3.exceptions.NewConnectionError: <urllib3.connection.VerifiedHTTPSConnection object at 0x7f1880309f98>: Failed to establish a new connection: [Errno -2] Name or service not known

During handling of the above exception, another exception occurred:

Traceback (most recent call last):
  File "/home/kyle/opt/anaconda3/lib/python3.6/site-packages/requests/adapters.py", line 440, in send
    timeout=timeout
  File "/home/kyle/opt/anaconda3/lib/python3.6/site-packages/urllib3/connectionpool.py", line 639, in urlopen
    _stacktrace=sys.exc_info()[2])
  File "/home/kyle/opt/anaconda3/lib/python3.6/site-packages/urllib3/util/retry.py", line 388, in increment
    raise MaxRetryError(_pool, url, error or ResponseError(cause))
urllib3.exceptions.MaxRetryError: HTTPSConnectionPool(host='gbfs.thehubway.com', port=443): Max retries exceeded with url: /gbfs/en/station_status.json (Caused by NewConnectionError('<urllib3.connection.VerifiedHTTPSConnection object at 0x7f1880309f98>: Failed to establish a new connection: [Errno -2] Name or service not known',))

During handling of the above exception, another exception occurred:

Traceback (most recent call last):
  File "/home/kyle/Documents/research/personal/hubway-expansion/code/01gbfs_scrape.py", line 16, in <module>
    data_station_status = requests.get(url_station_status).json()
  File "/home/kyle/opt/anaconda3/lib/python3.6/site-packages/requests/api.py", line 72, in get
    return request('get', url, params=params, **kwargs)
  File "/home/kyle/opt/anaconda3/lib/python3.6/site-packages/requests/api.py", line 58, in request
    return session.request(method=method, url=url, **kwargs)
  File "/home/kyle/opt/anaconda3/lib/python3.6/site-packages/requests/sessions.py", line 508, in request
    resp = self.send(prep, **send_kwargs)
  File "/home/kyle/opt/anaconda3/lib/python3.6/site-packages/requests/sessions.py", line 618, in send
    r = adapter.send(request, **kwargs)
  File "/home/kyle/opt/anaconda3/lib/python3.6/site-packages/requests/adapters.py", line 508, in send
    raise ConnectionError(e, request=request)
requests.exceptions.ConnectionError: HTTPSConnectionPool(host='gbfs.thehubway.com', port=443): Max retries exceeded with url: /gbfs/en/station_status.json (Caused by NewConnectionError('<urllib3.connection.VerifiedHTTPSConnection object at 0x7f1880309f98>: Failed to establish a new connection: [Errno -2] Name or service not known',))
Traceback (most recent call last):
  File "/home/kyle/Documents/research/personal/hubway-expansion/code/01gbfs_scrape.py", line 23, in <module>
    test = create_engine('mysql+pymysql://kyle:' + password + '@localhost/hubway')
NameError: name 'password' is not defined
Traceback (most recent call last):
  File "/home/kyle/Documents/research/personal/hubway-expansion/code/01gbfs_scrape.py", line 23, in <module>
    test = create_engine('mysql+pymysql://kyle:' + password + '@localhost/hubway')
NameError: name 'password' is not defined
Traceback (most recent call last):
  File "/home/kyle/Documents/research/personal/hubway-expansion/code/01gbfs_scrape.py", line 23, in <module>
    test = create_engine('mysql+pymysql://kyle:' + password + '@localhost/hubway')
NameError: name 'password' is not defined
Traceback (most recent call last):
  File "/home/kyle/Documents/research/personal/hubway-expansion/code/01gbfs_scrape.py", line 23, in <module>
    test = create_engine('mysql+pymysql://kyle:' + password + '@localhost/hubway')
NameError: name 'password' is not defined
Traceback (most recent call last):
  File "/home/kyle/Documents/research/personal/hubway-expansion/code/01gbfs_scrape.py", line 23, in <module>
    test = create_engine('mysql+pymysql://kyle:' + password + '@localhost/hubway')
NameError: name 'password' is not defined
Traceback (most recent call last):
  File "/home/kyle/Documents/research/personal/hubway-expansion/code/01gbfs_scrape.py", line 23, in <module>
    test = create_engine('mysql+pymysql://kyle:' + password + '@localhost/hubway')
NameError: name 'password' is not defined
Traceback (most recent call last):
  File "/home/kyle/Documents/research/personal/hubway-expansion/code/01gbfs_scrape.py", line 23, in <module>
    test = create_engine('mysql+pymysql://kyle:' + password + '@localhost/hubway')
NameError: name 'password' is not defined
Traceback (most recent call last):
  File "/home/kyle/Documents/research/personal/hubway-expansion/code/01gbfs_scrape.py", line 23, in <module>
    test = create_engine('mysql+pymysql://kyle:' + password + '@localhost/hubway')
NameError: name 'password' is not defined
Traceback (most recent call last):
  File "/home/kyle/Documents/research/personal/hubway-expansion/code/01gbfs_scrape.py", line 23, in <module>
    test = create_engine('mysql+pymysql://kyle:' + password + '@localhost/hubway')
NameError: name 'password' is not defined
Traceback (most recent call last):
  File "/home/kyle/Documents/research/personal/hubway-expansion/code/01gbfs_scrape.py", line 23, in <module>
    test = create_engine('mysql+pymysql://kyle:' + password + '@localhost/hubway')
NameError: name 'password' is not defined
Traceback (most recent call last):
  File "/home/kyle/Documents/research/personal/hubway-expansion/code/01gbfs_scrape.py", line 23, in <module>
    test = create_engine('mysql+pymysql://kyle:' + password + '@localhost/hubway')
NameError: name 'password' is not defined
Traceback (most recent call last):
  File "/home/kyle/Documents/research/personal/hubway-expansion/code/01gbfs_scrape.py", line 23, in <module>
    test = create_engine('mysql+pymysql://kyle:' + password + '@localhost/hubway')
NameError: name 'password' is not defined
Traceback (most recent call last):
  File "/home/kyle/Documents/research/personal/hubway-expansion/code/01gbfs_scrape.py", line 23, in <module>
    test = create_engine('mysql+pymysql://kyle:' + password + '@localhost/hubway')
NameError: name 'password' is not defined
Traceback (most recent call last):
  File "/home/kyle/Documents/research/personal/hubway-expansion/code/01gbfs_scrape.py", line 23, in <module>
    test = create_engine('mysql+pymysql://kyle:' + password + '@localhost/hubway')
NameError: name 'password' is not defined
Traceback (most recent call last):
  File "/home/kyle/Documents/research/personal/hubway-expansion/code/01gbfs_scrape.py", line 23, in <module>
    test = create_engine('mysql+pymysql://kyle:' + password + '@localhost/hubway')
NameError: name 'password' is not defined
Traceback (most recent call last):
  File "/home/kyle/Documents/research/personal/hubway-expansion/code/01gbfs_scrape.py", line 23, in <module>
    test = create_engine('mysql+pymysql://kyle:' + password + '@localhost/hubway')
NameError: name 'password' is not defined
Traceback (most recent call last):
  File "/home/kyle/Documents/research/personal/hubway-expansion/code/01gbfs_scrape.py", line 23, in <module>
    test = create_engine('mysql+pymysql://kyle:' + password + '@localhost/hubway')
NameError: name 'password' is not defined
Traceback (most recent call last):
  File "/home/kyle/Documents/research/personal/hubway-expansion/code/01gbfs_scrape.py", line 23, in <module>
    test = create_engine('mysql+pymysql://kyle:' + password + '@localhost/hubway')
NameError: name 'password' is not defined
Traceback (most recent call last):
  File "/home/kyle/Documents/research/personal/hubway-expansion/code/01gbfs_scrape.py", line 23, in <module>
    test = create_engine('mysql+pymysql://kyle:' + password + '@localhost/hubway')
NameError: name 'password' is not defined
Traceback (most recent call last):
  File "/home/kyle/Documents/research/personal/hubway-expansion/code/01gbfs_scrape.py", line 23, in <module>
    test = create_engine('mysql+pymysql://kyle:' + password + '@localhost/hubway')
NameError: name 'password' is not defined
Traceback (most recent call last):
  File "/home/kyle/Documents/research/personal/hubway-expansion/code/01gbfs_scrape.py", line 23, in <module>
    test = create_engine('mysql+pymysql://kyle:' + password + '@localhost/hubway')
NameError: name 'password' is not defined
Traceback (most recent call last):
  File "/home/kyle/Documents/research/personal/hubway-expansion/code/01gbfs_scrape.py", line 23, in <module>
    test = create_engine('mysql+pymysql://kyle:' + password + '@localhost/hubway')
NameError: name 'password' is not defined
Traceback (most recent call last):
  File "/home/kyle/Documents/research/personal/hubway-expansion/code/01gbfs_scrape.py", line 23, in <module>
    test = create_engine('mysql+pymysql://kyle:' + password + '@localhost/hubway')
NameError: name 'password' is not defined
Traceback (most recent call last):
  File "/home/kyle/Documents/research/personal/hubway-expansion/code/01gbfs_scrape.py", line 23, in <module>
    test = create_engine('mysql+pymysql://kyle:' + password + '@localhost/hubway')
NameError: name 'password' is not defined
Traceback (most recent call last):
  File "/home/kyle/Documents/research/personal/hubway-expansion/code/01gbfs_scrape.py", line 23, in <module>
    test = create_engine('mysql+pymysql://kyle:' + password + '@localhost/hubway')
NameError: name 'password' is not defined
Traceback (most recent call last):
  File "/home/kyle/Documents/research/personal/hubway-expansion/code/01gbfs_scrape.py", line 23, in <module>
    test = create_engine('mysql+pymysql://kyle:' + password + '@localhost/hubway')
NameError: name 'password' is not defined
Traceback (most recent call last):
  File "/home/kyle/Documents/research/personal/hubway-expansion/code/01gbfs_scrape.py", line 23, in <module>
    test = create_engine('mysql+pymysql://kyle:' + password + '@localhost/hubway')
NameError: name 'password' is not defined
Traceback (most recent call last):
  File "/home/kyle/Documents/research/personal/hubway-expansion/code/01gbfs_scrape.py", line 23, in <module>
    test = create_engine('mysql+pymysql://kyle:' + password + '@localhost/hubway')
NameError: name 'password' is not defined
Traceback (most recent call last):
  File "/home/kyle/Documents/research/personal/hubway-expansion/code/01gbfs_scrape.py", line 23, in <module>
    test = create_engine('mysql+pymysql://kyle:' + password + '@localhost/hubway')
NameError: name 'password' is not defined
Traceback (most recent call last):
  File "/home/kyle/Documents/research/personal/hubway-expansion/code/01gbfs_scrape.py", line 23, in <module>
    test = create_engine('mysql+pymysql://kyle:' + password + '@localhost/hubway')
NameError: name 'password' is not defined
Traceback (most recent call last):
  File "/home/kyle/Documents/research/personal/hubway-expansion/code/01gbfs_scrape.py", line 23, in <module>
    test = create_engine('mysql+pymysql://kyle:' + password + '@localhost/hubway')
NameError: name 'password' is not defined
Traceback (most recent call last):
  File "/home/kyle/Documents/research/personal/hubway-expansion/code/01gbfs_scrape.py", line 23, in <module>
    test = create_engine('mysql+pymysql://kyle:' + password + '@localhost/hubway')
NameError: name 'password' is not defined
Traceback (most recent call last):
  File "/home/kyle/Documents/research/personal/hubway-expansion/code/01gbfs_scrape.py", line 23, in <module>
    test = create_engine('mysql+pymysql://kyle:' + password + '@localhost/hubway')
NameError: name 'password' is not defined
Traceback (most recent call last):
  File "/home/kyle/Documents/research/personal/hubway-expansion/code/01gbfs_scrape.py", line 23, in <module>
    test = create_engine('mysql+pymysql://kyle:' + password + '@localhost/hubway')
NameError: name 'password' is not defined
Traceback (most recent call last):
  File "/home/kyle/Documents/research/personal/hubway-expansion/code/01gbfs_scrape.py", line 23, in <module>
    test = create_engine('mysql+pymysql://kyle:' + password + '@localhost/hubway')
NameError: name 'password' is not defined
Traceback (most recent call last):
  File "/home/kyle/Documents/research/personal/hubway-expansion/code/01gbfs_scrape.py", line 23, in <module>
    test = create_engine('mysql+pymysql://kyle:' + password + '@localhost/hubway')
NameError: name 'password' is not defined
Traceback (most recent call last):
  File "/home/kyle/Documents/research/personal/hubway-expansion/code/01gbfs_scrape.py", line 23, in <module>
    test = create_engine('mysql+pymysql://kyle:' + password + '@localhost/hubway')
NameError: name 'password' is not defined
Traceback (most recent call last):
  File "/home/kyle/Documents/research/personal/hubway-expansion/code/01gbfs_scrape.py", line 23, in <module>
    test = create_engine('mysql+pymysql://kyle:' + password + '@localhost/hubway')
NameError: name 'password' is not defined
Traceback (most recent call last):
  File "/home/kyle/Documents/research/personal/hubway-expansion/code/01gbfs_scrape.py", line 23, in <module>
    test = create_engine('mysql+pymysql://kyle:' + password + '@localhost/hubway')
NameError: name 'password' is not defined
Traceback (most recent call last):
  File "/home/kyle/Documents/research/personal/hubway-expansion/code/01gbfs_scrape.py", line 23, in <module>
    test = create_engine('mysql+pymysql://kyle:' + password + '@localhost/hubway')
NameError: name 'password' is not defined
Traceback (most recent call last):
  File "/home/kyle/Documents/research/personal/hubway-expansion/code/01gbfs_scrape.py", line 23, in <module>
    test = create_engine('mysql+pymysql://kyle:' + password + '@localhost/hubway')
NameError: name 'password' is not defined
Traceback (most recent call last):
  File "/home/kyle/Documents/research/personal/hubway-expansion/code/01gbfs_scrape.py", line 23, in <module>
    test = create_engine('mysql+pymysql://kyle:' + password + '@localhost/hubway')
NameError: name 'password' is not defined
Traceback (most recent call last):
  File "/home/kyle/Documents/research/personal/hubway-expansion/code/01gbfs_scrape.py", line 23, in <module>
    test = create_engine('mysql+pymysql://kyle:' + password + '@localhost/hubway')
NameError: name 'password' is not defined
Traceback (most recent call last):
  File "/home/kyle/Documents/research/personal/hubway-expansion/code/01gbfs_scrape.py", line 23, in <module>
    test = create_engine('mysql+pymysql://kyle:' + password + '@localhost/hubway')
NameError: name 'password' is not defined
Traceback (most recent call last):
  File "/home/kyle/Documents/research/personal/hubway-expansion/code/01gbfs_scrape.py", line 23, in <module>
    test = create_engine('mysql+pymysql://kyle:' + password + '@localhost/hubway')
NameError: name 'password' is not defined
Traceback (most recent call last):
  File "/home/kyle/Documents/research/personal/hubway-expansion/code/01gbfs_scrape.py", line 23, in <module>
    test = create_engine('mysql+pymysql://kyle:' + password + '@localhost/hubway')
NameError: name 'password' is not defined
Traceback (most recent call last):
  File "/home/kyle/Documents/research/personal/hubway-expansion/code/01gbfs_scrape.py", line 23, in <module>
    test = create_engine('mysql+pymysql://kyle:' + password + '@localhost/hubway')
NameError: name 'password' is not defined
Traceback (most recent call last):
  File "/home/kyle/Documents/research/personal/hubway-expansion/code/01gbfs_scrape.py", line 23, in <module>
    test = create_engine('mysql+pymysql://kyle:' + password + '@localhost/hubway')
NameError: name 'password' is not defined
Traceback (most recent call last):
  File "/home/kyle/Documents/research/personal/hubway-expansion/code/01gbfs_scrape.py", line 23, in <module>
    test = create_engine('mysql+pymysql://kyle:' + password + '@localhost/hubway')
NameError: name 'password' is not defined
Traceback (most recent call last):
  File "/home/kyle/Documents/research/personal/hubway-expansion/code/01gbfs_scrape.py", line 23, in <module>
    test = create_engine('mysql+pymysql://kyle:' + password + '@localhost/hubway')
NameError: name 'password' is not defined
Traceback (most recent call last):
  File "/home/kyle/Documents/research/personal/hubway-expansion/code/01gbfs_scrape.py", line 23, in <module>
    test = create_engine('mysql+pymysql://kyle:' + password + '@localhost/hubway')
NameError: name 'password' is not defined
Traceback (most recent call last):
  File "/home/kyle/Documents/research/personal/hubway-expansion/code/01gbfs_scrape.py", line 23, in <module>
    test = create_engine('mysql+pymysql://kyle:' + password + '@localhost/hubway')
NameError: name 'password' is not defined
Traceback (most recent call last):
  File "/home/kyle/Documents/research/personal/hubway-expansion/code/01gbfs_scrape.py", line 23, in <module>
    test = create_engine('mysql+pymysql://kyle:' + password + '@localhost/hubway')
NameError: name 'password' is not defined
Traceback (most recent call last):
  File "/home/kyle/Documents/research/personal/hubway-expansion/code/01gbfs_scrape.py", line 23, in <module>
    test = create_engine('mysql+pymysql://kyle:' + password + '@localhost/hubway')
NameError: name 'password' is not defined
Traceback (most recent call last):
  File "/home/kyle/Documents/research/personal/hubway-expansion/code/01gbfs_scrape.py", line 23, in <module>
    test = create_engine('mysql+pymysql://kyle:' + password + '@localhost/hubway')
NameError: name 'password' is not defined
Traceback (most recent call last):
  File "/home/kyle/Documents/research/personal/hubway-expansion/code/01gbfs_scrape.py", line 23, in <module>
    test = create_engine('mysql+pymysql://kyle:' + password + '@localhost/hubway')
NameError: name 'password' is not defined
Traceback (most recent call last):
  File "/home/kyle/Documents/research/personal/hubway-expansion/code/01gbfs_scrape.py", line 23, in <module>
    test = create_engine('mysql+pymysql://kyle:' + password + '@localhost/hubway')
NameError: name 'password' is not defined
Traceback (most recent call last):
  File "/home/kyle/Documents/research/personal/hubway-expansion/code/01gbfs_scrape.py", line 23, in <module>
    test = create_engine('mysql+pymysql://kyle:' + password + '@localhost/hubway')
NameError: name 'password' is not defined
Traceback (most recent call last):
  File "/home/kyle/Documents/research/personal/hubway-expansion/code/01gbfs_scrape.py", line 23, in <module>
    test = create_engine('mysql+pymysql://kyle:' + password + '@localhost/hubway')
NameError: name 'password' is not defined
Traceback (most recent call last):
  File "/home/kyle/Documents/research/personal/hubway-expansion/code/01gbfs_scrape.py", line 23, in <module>
    test = create_engine('mysql+pymysql://kyle:' + password + '@localhost/hubway')
NameError: name 'password' is not defined
Traceback (most recent call last):
  File "/home/kyle/Documents/research/personal/hubway-expansion/code/01gbfs_scrape.py", line 23, in <module>
    test = create_engine('mysql+pymysql://kyle:' + password + '@localhost/hubway')
NameError: name 'password' is not defined
Traceback (most recent call last):
  File "/home/kyle/Documents/research/personal/hubway-expansion/code/01gbfs_scrape.py", line 23, in <module>
    test = create_engine('mysql+pymysql://kyle:' + password + '@localhost/hubway')
NameError: name 'password' is not defined
Traceback (most recent call last):
  File "/home/kyle/Documents/research/personal/hubway-expansion/code/01gbfs_scrape.py", line 23, in <module>
    test = create_engine('mysql+pymysql://kyle:' + password + '@localhost/hubway')
NameError: name 'password' is not defined
Traceback (most recent call last):
  File "/home/kyle/Documents/research/personal/hubway-expansion/code/01gbfs_scrape.py", line 23, in <module>
    test = create_engine('mysql+pymysql://kyle:' + password + '@localhost/hubway')
NameError: name 'password' is not defined
Traceback (most recent call last):
  File "/home/kyle/Documents/research/personal/hubway-expansion/code/01gbfs_scrape.py", line 23, in <module>
    test = create_engine('mysql+pymysql://kyle:' + password + '@localhost/hubway')
NameError: name 'password' is not defined
Traceback (most recent call last):
  File "/home/kyle/Documents/research/personal/hubway-expansion/code/01gbfs_scrape.py", line 23, in <module>
    test = create_engine('mysql+pymysql://kyle:' + password + '@localhost/hubway')
NameError: name 'password' is not defined
Traceback (most recent call last):
  File "/home/kyle/Documents/research/personal/hubway-expansion/code/01gbfs_scrape.py", line 23, in <module>
    test = create_engine('mysql+pymysql://kyle:' + password + '@localhost/hubway')
NameError: name 'password' is not defined
Traceback (most recent call last):
  File "/home/kyle/Documents/research/personal/hubway-expansion/code/01gbfs_scrape.py", line 23, in <module>
    test = create_engine('mysql+pymysql://kyle:' + password + '@localhost/hubway')
NameError: name 'password' is not defined
Traceback (most recent call last):
  File "/home/kyle/Documents/research/personal/hubway-expansion/code/01gbfs_scrape.py", line 23, in <module>
    test = create_engine('mysql+pymysql://kyle:' + password + '@localhost/hubway')
NameError: name 'password' is not defined
Traceback (most recent call last):
  File "/home/kyle/Documents/research/personal/hubway-expansion/code/01gbfs_scrape.py", line 23, in <module>
    test = create_engine('mysql+pymysql://kyle:' + password + '@localhost/hubway')
NameError: name 'password' is not defined
Traceback (most recent call last):
  File "/home/kyle/Documents/research/personal/hubway-expansion/code/01gbfs_scrape.py", line 23, in <module>
    test = create_engine('mysql+pymysql://kyle:' + password + '@localhost/hubway')
NameError: name 'password' is not defined
Traceback (most recent call last):
  File "/home/kyle/Documents/research/personal/hubway-expansion/code/01gbfs_scrape.py", line 23, in <module>
    test = create_engine('mysql+pymysql://kyle:' + password + '@localhost/hubway')
NameError: name 'password' is not defined
Traceback (most recent call last):
  File "/home/kyle/Documents/research/personal/hubway-expansion/code/01gbfs_scrape.py", line 23, in <module>
    test = create_engine('mysql+pymysql://kyle:' + password + '@localhost/hubway')
NameError: name 'password' is not defined
Traceback (most recent call last):
  File "/home/kyle/Documents/research/personal/hubway-expansion/code/01gbfs_scrape.py", line 23, in <module>
    test = create_engine('mysql+pymysql://kyle:' + password + '@localhost/hubway')
NameError: name 'password' is not defined
Traceback (most recent call last):
  File "/home/kyle/Documents/research/personal/hubway-expansion/code/01gbfs_scrape.py", line 23, in <module>
    test = create_engine('mysql+pymysql://kyle:' + password + '@localhost/hubway')
NameError: name 'password' is not defined
Traceback (most recent call last):
  File "/home/kyle/Documents/research/personal/hubway-expansion/code/01gbfs_scrape.py", line 23, in <module>
    test = create_engine('mysql+pymysql://kyle:' + password + '@localhost/hubway')
NameError: name 'password' is not defined
Traceback (most recent call last):
  File "/home/kyle/Documents/research/personal/hubway-expansion/code/01gbfs_scrape.py", line 23, in <module>
    test = create_engine('mysql+pymysql://kyle:' + password + '@localhost/hubway')
NameError: name 'password' is not defined
Traceback (most recent call last):
  File "/home/kyle/Documents/research/personal/hubway-expansion/code/01gbfs_scrape.py", line 23, in <module>
    test = create_engine('mysql+pymysql://kyle:' + password + '@localhost/hubway')
NameError: name 'password' is not defined
Traceback (most recent call last):
  File "/home/kyle/Documents/research/personal/hubway-expansion/code/01gbfs_scrape.py", line 23, in <module>
    test = create_engine('mysql+pymysql://kyle:' + password + '@localhost/hubway')
NameError: name 'password' is not defined
Traceback (most recent call last):
  File "/home/kyle/Documents/research/personal/hubway-expansion/code/01gbfs_scrape.py", line 23, in <module>
    test = create_engine('mysql+pymysql://kyle:' + password + '@localhost/hubway')
NameError: name 'password' is not defined
Traceback (most recent call last):
  File "/home/kyle/Documents/research/personal/hubway-expansion/code/01gbfs_scrape.py", line 23, in <module>
    test = create_engine('mysql+pymysql://kyle:' + password + '@localhost/hubway')
NameError: name 'password' is not defined
Traceback (most recent call last):
  File "/home/kyle/Documents/research/personal/hubway-expansion/code/01gbfs_scrape.py", line 23, in <module>
    test = create_engine('mysql+pymysql://kyle:' + password + '@localhost/hubway')
NameError: name 'password' is not defined
Traceback (most recent call last):
  File "/home/kyle/Documents/research/personal/hubway-expansion/code/01gbfs_scrape.py", line 23, in <module>
    test = create_engine('mysql+pymysql://kyle:' + password + '@localhost/hubway')
NameError: name 'password' is not defined
Traceback (most recent call last):
  File "/home/kyle/Documents/research/personal/hubway-expansion/code/01gbfs_scrape.py", line 23, in <module>
    test = create_engine('mysql+pymysql://kyle:' + password + '@localhost/hubway')
NameError: name 'password' is not defined
